<?xml version="1.0" ?>
<!-- =================================================================================== -->
<!-- |    This document was autogenerated by xacro from homebot.urdf.xacro             | -->
<!-- |    EDITING THIS FILE BY HAND IS NOT RECOMMENDED                                 | -->
<!-- =================================================================================== -->
<robot name="home_robot">
  <!-- Platforms column macro -->
  <joint name="platform_column_joint" type="fixed">
    <parent link="base_link"/>
    <child link="platform_column_link"/>
    <origin xyz="0.07 0 0.22"/>
  </joint>
  <link name="platform_column_link">
    <visual>
      <geometry>
        <cylinder length="0.455" radius="0.02"/>
      </geometry>
      <origin rpy="0 0 0" xyz="0 0 0"/>
      <material name="dark"/>
    </visual>
    <collision>
      <origin rpy="0 0 0" xyz="0 0 0"/>
      <geometry>
        <cylinder length="0.8" radius="0.04"/>
      </geometry>
    </collision>
    <inertial>
      <origin rpy="0 0 0" xyz="0 0 0"/>
      <mass value="1.25"/>
      <inertia ixx="0.045453" ixy="0" ixz="0" iyy="0.049627" iyz="0" izz="0.004174"/>
    </inertial>
  </link>
  &gt;
 

  <!-- Platform dimensions -->
  <link name="base_link">
    <visual>
      <origin xyz="0 0 0"/>
      <geometry>
        <box size="0.53 0.56 0.035"/>
      </geometry>
      <material name="light_black"/>
    </visual>
    <collision>
      <origin xyz="0 0 0"/>
      <geometry>
        <box size="0.53 0.56 0.07"/>
      </geometry>
    </collision>
  </link>
  <!-- Upper platform -->
  <joint name="platform2_joint" type="fixed">
    <parent link="base_link"/>
    <child link="platform2_link"/>
    <origin xyz="0.09000000000000002 0 0.47"/>
  </joint>
  <link name="platform2_link">
    <visual>
      <origin rpy="0 0 0" xyz="0 0 0"/>
      <geometry>
        <box size="0.3 0.35 0.02"/>
      </geometry>
      <material name="light_black"/>
    </visual>
    <collision>
      <origin rpy="0 0 0" xyz="0 0 0"/>
      <geometry>
        <box size="0.3 0.35 0.02"/>
      </geometry>
    </collision>
    <inertial>
      <origin rpy="0 0 0" xyz="0 0 0"/>
      <mass value="3.12"/>
      <inertia ixx="0.065" ixy="0" ixz="0" iyy="0.0816" iyz="0" izz="0.147"/>
    </inertial>
  </link>
  <!-- Lower platform -->
  <joint name="platform1_joint" type="fixed">
    <parent link="base_link"/>
    <child link="platform1_link"/>
    <origin xyz="0.265 0 0.39"/>
  </joint>
  <link name="platform1_link">
    <visual>
      <origin rpy="0 0 0" xyz="0 0 0"/>
      <geometry>
        <box size="0.35 0.4 0.02"/>
      </geometry>
      <material name="light_black"/>
    </visual>
    <collision>
      <origin rpy="0 0 0" xyz="0 0 0"/>
      <geometry>
        <box size="0.35 0.4 0.02"/>
      </geometry>
    </collision>
    <inertial>
      <origin rpy="0 0 0" xyz="0 0 0"/>
      <mass value="2.52"/>
      <inertia ixx="0.065" ixy="0" ixz="0" iyy="0.0816" iyz="0" izz="0.147"/>
    </inertial>
  </link>
  <!-- Sensors -->
  <material name="rs_t265_aluminum">
    <color rgba="0.5 0.5 0.5 1"/>
  </material>
  <!-- camera body, with origin at camera_link -->
  <joint name="rs_t265_pose_frame_joint" type="fixed">
    <origin rpy="0 0 0" xyz="0.455 0 0.39"/>
    <parent link="base_link"/>
    <child link="rs_t265_pose_frame"/>
  </joint>
  <link name="rs_t265_pose_frame"/>
  <joint name="rs_t265_pose_joint" type="fixed">
    <origin rpy="1.5707963267948966 0 -1.5707963267948966" xyz="0 0 0"/>
    <parent link="rs_t265_pose_frame"/>
    <child link="rs_t265_link"/>
  </joint>
  <link name="rs_t265_link">
    <visual>
      <origin rpy="0 0 0" xyz="0 0 0"/>
      <geometry>
        <mesh filename="package://robot_description/meshes/sensors/t265.stl"/>
      </geometry>
      <material name="rs_t265_aluminum"/>
    </visual>
    <collision>
      <origin rpy="0 0 0" xyz="0 0 0"/>
      <geometry>
        <mesh filename="package://robot_description/meshes/sensors/t265.stl"/>
      </geometry>
    </collision>
    <inertial>
      <!-- The following are not reliable values, and should not be used for modeling -->
      <mass value="0.068024"/>
      <origin xyz="0 0 0"/>
      <inertia ixx="0.0000039782" ixy="0.0" ixz="0.000000034641" iyy="0.000065045" iyz="0.0" izz="0.000067499"/>
    </inertial>
  </link>
  <joint name="rs_t265_fisheye1_rgb_joint" type="fixed">
    <origin rpy="0 1.5707963267948966 1.5707963267948966" xyz="-0.0411 0.0 0.0"/>
    <parent link="rs_t265_link"/>
    <child link="rs_t265_fisheye1_rgb_frame"/>
  </joint>
  <link name="rs_t265_fisheye1_rgb_frame"/>
  <joint name="rs_t265_fisheye2_rgb_joint" type="fixed">
    <origin rpy="0 1.5707963267948966 1.5707963267948966" xyz="0.0229 0.0 0.0"/>
    <parent link="rs_t265_link"/>
    <child link="rs_t265_fisheye2_rgb_frame"/>
  </joint>
  <link name="rs_t265_fisheye2_rgb_frame"/>
  <joint name="rs_t265_fisheye1_optical_joint" type="fixed">
    <origin rpy="-1.5707963267948966 0 -1.5707963267948966" xyz="0 0 0"/>
    <parent link="rs_t265_fisheye1_rgb_frame"/>
    <child link="rs_t265_fisheye1_optical_frame"/>
  </joint>
  <link name="rs_t265_fisheye1_optical_frame"/>
  <joint name="rs_t265_fisheye2_optical_joint" type="fixed">
    <origin rpy="-1.5707963267948966 0 -1.5707963267948966" xyz="0 0 0"/>
    <parent link="rs_t265_fisheye2_rgb_frame"/>
    <child link="rs_t265_fisheye2_optical_frame"/>
  </joint>
  <link name="rs_t265_fisheye2_optical_frame"/>
  <!-- camera depth joints and links -->
  <joint name="rs_t265_gyro_optical_joint" type="fixed">
    <origin rpy="0 3.141592653589793 0" xyz="-0.0311 0 0.00655"/>
    <parent link="rs_t265_link"/>
    <child link="rs_t265_gyro_optical_frame"/>
  </joint>
  <link name="rs_t265_gyro_optical_frame"/>
  <joint name="rs_t265_accel_optical_joint" type="fixed">
    <origin rpy="0 0 0" xyz="0 0 0"/>
    <parent link="rs_t265_gyro_optical_frame"/>
    <child link="rs_t265_accel_optical_frame"/>
  </joint>
  <link name="rs_t265_accel_optical_frame"/>
  <joint name="velodyne_base_mount_joint" type="fixed">
    <origin rpy="0 0 0" xyz="0.365 0 0.4"/>
    <parent link="base_link"/>
    <child link="velodyne_base_link"/>
  </joint>
  <link name="velodyne_base_link">
    <inertial>
      <mass value="0.83"/>
      <origin xyz="0 0 0.03585"/>
      <inertia ixx="0.000908059425" ixy="0" ixz="0" iyy="0.000908059425" iyz="0" izz="0.0011049624"/>
    </inertial>
    <visual>
      <geometry>
        <mesh filename="package://robot_description/meshes/sensors/VLP16_base_1.dae"/>
      </geometry>
    </visual>
    <visual>
      <geometry>
        <mesh filename="package://robot_description/meshes/sensors/VLP16_base_2.dae"/>
      </geometry>
    </visual>
    <collision>
      <origin rpy="0 0 0" xyz="0 0 0.03585"/>
      <geometry>
        <cylinder length="0.0717" radius="0.0516"/>
      </geometry>
    </collision>
  </link>
  <joint name="velodyne_base_scan_joint" type="fixed">
    <origin rpy="0 0 0" xyz="0 0 0.0377"/>
    <parent link="velodyne_base_link"/>
    <child link="velodyne"/>
  </joint>
  <link name="velodyne">
    <inertial>
      <mass value="0.01"/>
      <origin xyz="0 0 0"/>
      <inertia ixx="1e-7" ixy="0" ixz="0" iyy="1e-7" iyz="0" izz="1e-7"/>
    </inertial>
    <visual>
      <origin xyz="0 0 -0.0377"/>
      <geometry>
        <mesh filename="package://robot_description/meshes/sensors/VLP16_scan.dae"/>
      </geometry>
    </visual>
  </link>
  <!-- Gazebo requires the velodyne_gazebo_plugins package -->
  <gazebo reference="velodyne">
    <sensor name="velodyne-VLP16" type="gpu_ray">
      <pose>0 0 0 0 0 0</pose>
      <visualize>false</visualize>
      <update_rate>10</update_rate>
      <ray>
        <scan>
          <horizontal>
            <samples>440</samples>
            <resolution>1</resolution>
            <min_angle>-3.141592653589793</min_angle>
            <max_angle>3.141592653589793</max_angle>
          </horizontal>
          <vertical>
            <samples>16</samples>
            <resolution>1</resolution>
            <min_angle>-0.2617993877991494</min_angle>
            <max_angle> 0.2617993877991494</max_angle>
          </vertical>
        </scan>
        <range>
          <min>0.3</min>
          <max>131.0</max>
          <resolution>0.001</resolution>
        </range>
        <noise>
          <type>gaussian</type>
          <mean>0.0</mean>
          <stddev>0.0</stddev>
        </noise>
      </ray>
      <plugin filename="libgazebo_ros_velodyne_gpu_laser.so" name="gazebo_ros_laser_controller">
        <topicName>/velodyne_points2</topicName>
        <frameName>velodyne</frameName>
        <organize_cloud>False</organize_cloud>
        <min_range>0.9</min_range>
        <max_range>130.0</max_range>
        <gaussianNoise>0.008</gaussianNoise>
      </plugin>
    </sensor>
  </gazebo>
  <joint name="wheel_back_left_joint" type="continuous">
    <parent link="base_link"/>
    <child link="wheel_back_left_link"/>
    <axis xyz="0 0 1"/>
    <origin rpy="-1.5707963267948966 0 0" xyz="-0.265 -0.28 -0.05"/>
  </joint>
  <link name="wheel_back_left_link">
    <visual>
      <geometry>
        <cylinder length="0.03" radius="0.02"/>
      </geometry>
      <origin rpy="0 0 0" xyz="0 0 0"/>
      <material name="dark"/>
    </visual>
    <collision>
      <!--   
   <origin xyz="-0.064 0 0.047" rpy="0 0 0"/>
 -->
      <origin rpy="0 0 0" xyz="0 0 0"/>
      <geometry>
        <cylinder length="0.03" radius="0.02"/>
      </geometry>
    </collision>
    <inertial>
      <!-- Center of mass origin -->
      <origin xyz="0 0 0"/>
      <mass value="3.4"/>
      <inertia ixx="0.0067" ixy="-0" ixz="0" iyy="0.0123" iyz="0" izz="0.0067"/>
    </inertial>
  </link>
  <joint name="wheel_back_right_joint" type="continuous">
    <parent link="base_link"/>
    <child link="wheel_back_right_link"/>
    <axis xyz="0 0 1"/>
    <origin rpy="-1.5707963267948966 0 0" xyz="-0.265 0.28 -0.05"/>
  </joint>
  <link name="wheel_back_right_link">
    <visual>
      <geometry>
        <cylinder length="0.03" radius="0.02"/>
      </geometry>
      <origin rpy="0 0 0" xyz="0 0 0"/>
      <material name="dark"/>
    </visual>
    <collision>
      <!--   
   <origin xyz="-0.064 0 0.047" rpy="0 0 0"/>
 -->
      <origin rpy="0 0 0" xyz="0 0 0"/>
      <geometry>
        <cylinder length="0.03" radius="0.02"/>
      </geometry>
    </collision>
    <inertial>
      <!-- Center of mass origin -->
      <origin xyz="0 0 0"/>
      <mass value="3.4"/>
      <inertia ixx="0.0067" ixy="-0" ixz="0" iyy="0.0123" iyz="0" izz="0.0067"/>
    </inertial>
  </link>
  <joint name="wheel_front_left_joint" type="continuous">
    <parent link="base_link"/>
    <child link="wheel_front_left_link"/>
    <axis xyz="0 0 1"/>
    <origin rpy="-1.5707963267948966 0 0" xyz="0.265 -0.28 -0.05"/>
  </joint>
  <link name="wheel_front_left_link">
    <visual>
      <geometry>
        <cylinder length="0.03" radius="0.02"/>
      </geometry>
      <origin rpy="0 0 0" xyz="0 0 0"/>
      <material name="dark"/>
    </visual>
    <collision>
      <!--   
   <origin xyz="-0.064 0 0.047" rpy="0 0 0"/>
 -->
      <origin rpy="0 0 0" xyz="0 0 0"/>
      <geometry>
        <cylinder length="0.03" radius="0.02"/>
      </geometry>
    </collision>
    <inertial>
      <!-- Center of mass origin -->
      <origin xyz="0 0 0"/>
      <mass value="3.4"/>
      <inertia ixx="0.0067" ixy="-0" ixz="0" iyy="0.0123" iyz="0" izz="0.0067"/>
    </inertial>
  </link>
  <joint name="wheel_front_right_joint" type="continuous">
    <parent link="base_link"/>
    <child link="wheel_front_right_link"/>
    <axis xyz="0 0 1"/>
    <origin rpy="-1.5707963267948966 0 0" xyz="0.265 0.28 -0.05"/>
  </joint>
  <link name="wheel_front_right_link">
    <visual>
      <geometry>
        <cylinder length="0.03" radius="0.02"/>
      </geometry>
      <origin rpy="0 0 0" xyz="0 0 0"/>
      <material name="dark"/>
    </visual>
    <collision>
      <!--   
   <origin xyz="-0.064 0 0.047" rpy="0 0 0"/>
 -->
      <origin rpy="0 0 0" xyz="0 0 0"/>
      <geometry>
        <cylinder length="0.03" radius="0.02"/>
      </geometry>
    </collision>
    <inertial>
      <!-- Center of mass origin -->
      <origin xyz="0 0 0"/>
      <mass value="3.4"/>
      <inertia ixx="0.0067" ixy="-0" ixz="0" iyy="0.0123" iyz="0" izz="0.0067"/>
    </inertial>
  </link>
</robot>
